INFO flwr 2024-01-18 11:20:34,689 | app.py:148 | Starting Flower server, config: ServerConfig(num_rounds=400, round_timeout=None)
INFO flwr 2024-01-18 11:20:34,829 | app.py:168 | Flower ECE: gRPC server running (400 rounds), SSL is disabled
INFO flwr 2024-01-18 11:20:34,829 | server.py:86 | Initializing global parameters
INFO flwr 2024-01-18 11:20:34,829 | server.py:273 | Requesting initial parameters from one random client
server booted up. starting clients...
INFO flwr 2024-01-18 11:22:03,142 | server.py:277 | Received initial parameters from one random client
INFO flwr 2024-01-18 11:22:03,143 | server.py:88 | Evaluating initial parameters
INFO flwr 2024-01-18 11:22:03,183 | grpc.py:50 | Opened insecure gRPC connection (no certificates were passed)
DEBUG flwr 2024-01-18 11:22:03,189 | connection.py:39 | ChannelConnectivity.IDLE
DEBUG flwr 2024-01-18 11:22:03,189 | connection.py:39 | ChannelConnectivity.CONNECTING
DEBUG flwr 2024-01-18 11:22:03,193 | connection.py:39 | ChannelConnectivity.READY
INFO flwr 2024-01-18 11:22:03,515 | grpc.py:50 | Opened insecure gRPC connection (no certificates were passed)
DEBUG flwr 2024-01-18 11:22:03,520 | connection.py:39 | ChannelConnectivity.IDLE
DEBUG flwr 2024-01-18 11:22:03,521 | connection.py:39 | ChannelConnectivity.CONNECTING
DEBUG flwr 2024-01-18 11:22:03,525 | connection.py:39 | ChannelConnectivity.READY
INFO flwr 2024-01-18 11:22:04,037 | grpc.py:50 | Opened insecure gRPC connection (no certificates were passed)
DEBUG flwr 2024-01-18 11:22:04,042 | connection.py:39 | ChannelConnectivity.IDLE
DEBUG flwr 2024-01-18 11:22:04,042 | connection.py:39 | ChannelConnectivity.CONNECTING
DEBUG flwr 2024-01-18 11:22:04,046 | connection.py:39 | ChannelConnectivity.READY
INFO flwr 2024-01-18 11:22:04,182 | grpc.py:50 | Opened insecure gRPC connection (no certificates were passed)
DEBUG flwr 2024-01-18 11:22:04,188 | connection.py:39 | ChannelConnectivity.IDLE
DEBUG flwr 2024-01-18 11:22:04,188 | connection.py:39 | ChannelConnectivity.CONNECTING
DEBUG flwr 2024-01-18 11:22:04,192 | connection.py:39 | ChannelConnectivity.READY
INFO flwr 2024-01-18 11:22:04,745 | grpc.py:50 | Opened insecure gRPC connection (no certificates were passed)
DEBUG flwr 2024-01-18 11:22:04,750 | connection.py:39 | ChannelConnectivity.IDLE
DEBUG flwr 2024-01-18 11:22:04,750 | connection.py:39 | ChannelConnectivity.CONNECTING
DEBUG flwr 2024-01-18 11:22:04,755 | connection.py:39 | ChannelConnectivity.READY
INFO flwr 2024-01-18 11:22:04,784 | grpc.py:50 | Opened insecure gRPC connection (no certificates were passed)
INFO flwr 2024-01-18 11:22:04,790 | grpc.py:50 | Opened insecure gRPC connection (no certificates were passed)
INFO flwr 2024-01-18 11:22:04,800 | grpc.py:50 | Opened insecure gRPC connection (no certificates were passed)
DEBUG flwr 2024-01-18 11:22:04,801 | connection.py:39 | ChannelConnectivity.IDLE
DEBUG flwr 2024-01-18 11:22:04,802 | connection.py:39 | ChannelConnectivity.CONNECTING
DEBUG flwr 2024-01-18 11:22:04,804 | connection.py:39 | ChannelConnectivity.IDLE
DEBUG flwr 2024-01-18 11:22:04,804 | connection.py:39 | ChannelConnectivity.CONNECTING
DEBUG flwr 2024-01-18 11:22:04,807 | connection.py:39 | ChannelConnectivity.READY
DEBUG flwr 2024-01-18 11:22:04,808 | connection.py:39 | ChannelConnectivity.READY
INFO flwr 2024-01-18 11:22:04,815 | grpc.py:50 | Opened insecure gRPC connection (no certificates were passed)
DEBUG flwr 2024-01-18 11:22:04,819 | connection.py:39 | ChannelConnectivity.IDLE
DEBUG flwr 2024-01-18 11:22:04,819 | connection.py:39 | ChannelConnectivity.CONNECTING
INFO flwr 2024-01-18 11:22:04,825 | grpc.py:50 | Opened insecure gRPC connection (no certificates were passed)
DEBUG flwr 2024-01-18 11:22:04,827 | connection.py:39 | ChannelConnectivity.IDLE
DEBUG flwr 2024-01-18 11:22:04,827 | connection.py:39 | ChannelConnectivity.CONNECTING
DEBUG flwr 2024-01-18 11:22:04,824 | connection.py:39 | ChannelConnectivity.READY
DEBUG flwr 2024-01-18 11:22:04,829 | connection.py:39 | ChannelConnectivity.IDLE
DEBUG flwr 2024-01-18 11:22:04,829 | connection.py:39 | ChannelConnectivity.CONNECTING
DEBUG flwr 2024-01-18 11:22:04,831 | connection.py:39 | ChannelConnectivity.READY
DEBUG flwr 2024-01-18 11:22:04,833 | connection.py:39 | ChannelConnectivity.READY
INFO flwr 2024-01-18 11:22:05,220 | server.py:91 | initial parameters (loss, other metrics): 2.30748080749263, {'accuracy': 0.1026}
INFO flwr 2024-01-18 11:22:05,221 | server.py:101 | FL starting
DEBUG flwr 2024-01-18 11:22:05,221 | server.py:218 | fit_round 1: strategy sampled 11 clients (out of 11)
DEBUG flwr 2024-01-18 11:22:34,460 | server.py:232 | fit_round 1 received 11 results and 0 failures
args.central: False
server strategy: ADMM
number of clients: 10
round:      0
Server-side evaluation loss 2.30748080749263 / accuracy 0.1026
Traceback (most recent call last):
  File "/tudelft.net/staff-bulk/ewi/insy/DBL/swiergarst/RP_FL/run_server.py", line 161, in <module>
    fl.server.start_server(config=fl.server.ServerConfig(num_rounds=NUM_ROUNDS), strategy=strat)
  File "/tudelft.net/staff-bulk/ewi/insy/DBL/swiergarst/envs/flower2en/lib/python3.9/site-packages/flwr/server/app.py", line 176, in start_server
    hist = _fl(
  File "/tudelft.net/staff-bulk/ewi/insy/DBL/swiergarst/envs/flower2en/lib/python3.9/site-packages/flwr/server/app.py", line 217, in _fl
    hist = server.fit(num_rounds=config.num_rounds, timeout=config.round_timeout)
  File "/tudelft.net/staff-bulk/ewi/insy/DBL/swiergarst/envs/flower2en/lib/python3.9/site-packages/flwr/server/server.py", line 106, in fit
    res_fit = self.fit_round(server_round=current_round, timeout=timeout)
  File "/tudelft.net/staff-bulk/ewi/insy/DBL/swiergarst/envs/flower2en/lib/python3.9/site-packages/flwr/server/server.py", line 244, in fit_round
    ] = self.strategy.aggregate_fit(server_round, results, failures)
  File "/tudelft.net/staff-bulk/ewi/insy/DBL/swiergarst/RP_FL/src/ADMM_strategy.py", line 28, in aggregate_fit
    y_local = json.loads(res.metrics["Y"].decode("utf-8"))
KeyError: 'Y'
Exception in thread Thread-1:
Traceback (most recent call last):
  File "/tudelft.net/staff-bulk/ewi/insy/DBL/swiergarst/envs/flower2en/lib/python3.9/threading.py", line 973, in _bootstrap_inner
    self.run()
  File "/tudelft.net/staff-bulk/ewi/insy/DBL/swiergarst/envs/flower2en/lib/python3.9/threading.py", line 910, in run
    self._target(*self._args, **self._kwargs)
  File "/tudelft.net/staff-bulk/ewi/insy/DBL/swiergarst/envs/flower2en/lib/python3.9/site-packages/grpc/_server.py", line 1212, in _serve
    if not _process_event_and_continue(state, event):
  File "/tudelft.net/staff-bulk/ewi/insy/DBL/swiergarst/envs/flower2en/lib/python3.9/site-packages/grpc/_server.py", line 1172, in _process_event_and_continue
    rpc_state, rpc_future = _handle_call(
  File "/tudelft.net/staff-bulk/ewi/insy/DBL/swiergarst/envs/flower2en/lib/python3.9/site-packages/grpc/_server.py", line 1049, in _handle_call
    return _handle_with_method_handler(
  File "/tudelft.net/staff-bulk/ewi/insy/DBL/swiergarst/envs/flower2en/lib/python3.9/site-packages/grpc/_server.py", line 987, in _handle_with_method_handler
    return state, _handle_stream_stream(
  File "/tudelft.net/staff-bulk/ewi/insy/DBL/swiergarst/envs/flower2en/lib/python3.9/site-packages/grpc/_server.py", line 914, in _handle_stream_stream
    return thread_pool.submit(
  File "/tudelft.net/staff-bulk/ewi/insy/DBL/swiergarst/envs/flower2en/lib/python3.9/concurrent/futures/thread.py", line 169, in submit
    raise RuntimeError('cannot schedule new futures after '
RuntimeError: cannot schedule new futures after interpreter shutdown
DEBUG flwr 2024-01-18 11:26:40,709 | connection.py:39 | ChannelConnectivity.IDLE
DEBUG flwr 2024-01-18 11:26:40,714 | connection.py:39 | ChannelConnectivity.IDLE
DEBUG flwr 2024-01-18 11:26:42,205 | connection.py:113 | gRPC channel closed
booting up client 9
Traceback (most recent call last):
  File "/tudelft.net/staff-bulk/ewi/insy/DBL/swiergarst/RP_FL/run_client.py", line 55, in <module>
    fl.client.start_numpy_client(server_address = "[::]:8080", client = client)
  File "/tudelft.net/staff-bulk/ewi/insy/DBL/swiergarst/envs/flower2en/lib/python3.9/site-packages/flwr/client/app.py", line 252, in start_numpy_client
    start_client(
  File "/tudelft.net/staff-bulk/ewi/insy/DBL/swiergarst/envs/flower2en/lib/python3.9/site-packages/flwr/client/app.py", line 174, in start_client
    server_message = receive()
  File "/tudelft.net/staff-bulk/ewi/insy/DBL/swiergarst/envs/flower2en/lib/python3.9/site-packages/flwr/client/grpc_client/connection.py", line 105, in <lambda>
DEBUG flwr 2024-01-18 11:26:42,361 | connection.py:113 | gRPC channel closed
booting up client 6
Traceback (most recent call last):
  File "/tudelft.net/staff-bulk/ewi/insy/DBL/swiergarst/RP_FL/run_client.py", line 55, in <module>
    receive: Callable[[], ServerMessage] = lambda: next(server_message_iterator)
  File "/tudelft.net/staff-bulk/ewi/insy/DBL/swiergarst/envs/flower2en/lib/python3.9/site-packages/grpc/_channel.py", line 541, in __next__
    fl.client.start_numpy_client(server_address = "[::]:8080", client = client)
  File "/tudelft.net/staff-bulk/ewi/insy/DBL/swiergarst/envs/flower2en/lib/python3.9/site-packages/flwr/client/app.py", line 252, in start_numpy_client
    return self._next()
  File "/tudelft.net/staff-bulk/ewi/insy/DBL/swiergarst/envs/flower2en/lib/python3.9/site-packages/grpc/_channel.py", line 950, in _next
    start_client(
  File "/tudelft.net/staff-bulk/ewi/insy/DBL/swiergarst/envs/flower2en/lib/python3.9/site-packages/flwr/client/app.py", line 174, in start_client
    raise self
grpc._channel._MultiThreadedRendezvous: <_MultiThreadedRendezvous of RPC that terminated with:
	status = StatusCode.UNAVAILABLE
	details = "Socket closed"
	debug_error_string = "UNKNOWN:Error received from peer ipv6:%5B::%5D:8080 {grpc_message:"Socket closed", grpc_status:14, created_time:"2024-01-18T11:26:40.693289223+01:00"}"
>
    server_message = receive()
  File "/tudelft.net/staff-bulk/ewi/insy/DBL/swiergarst/envs/flower2en/lib/python3.9/site-packages/flwr/client/grpc_client/connection.py", line 105, in <lambda>
DEBUG flwr 2024-01-18 11:26:42,532 | connection.py:39 | ChannelConnectivity.IDLE
    receive: Callable[[], ServerMessage] = lambda: next(server_message_iterator)
  File "/tudelft.net/staff-bulk/ewi/insy/DBL/swiergarst/envs/flower2en/lib/python3.9/site-packages/grpc/_channel.py", line 541, in __next__
    return self._next()
  File "/tudelft.net/staff-bulk/ewi/insy/DBL/swiergarst/envs/flower2en/lib/python3.9/site-packages/grpc/_channel.py", line 950, in _next
    raise self
grpc._channel._MultiThreadedRendezvous: <_MultiThreadedRendezvous of RPC that terminated with:
	status = StatusCode.UNAVAILABLE
	details = "Socket closed"
	debug_error_string = "UNKNOWN:Error received from peer ipv6:%5B::%5D:8080 {grpc_message:"Socket closed", grpc_status:14, created_time:"2024-01-18T11:26:40.693288221+01:00"}"
>
DEBUG flwr 2024-01-18 11:26:42,736 | connection.py:113 | gRPC channel closed
booting up client 7
Traceback (most recent call last):
  File "/tudelft.net/staff-bulk/ewi/insy/DBL/swiergarst/RP_FL/run_client.py", line 55, in <module>
    fl.client.start_numpy_client(server_address = "[::]:8080", client = client)
  File "/tudelft.net/staff-bulk/ewi/insy/DBL/swiergarst/envs/flower2en/lib/python3.9/site-packages/flwr/client/app.py", line 252, in start_numpy_client
    start_client(
  File "/tudelft.net/staff-bulk/ewi/insy/DBL/swiergarst/envs/flower2en/lib/python3.9/site-packages/flwr/client/app.py", line 174, in start_client
    server_message = receive()
  File "/tudelft.net/staff-bulk/ewi/insy/DBL/swiergarst/envs/flower2en/lib/python3.9/site-packages/flwr/client/grpc_client/connection.py", line 105, in <lambda>
    receive: Callable[[], ServerMessage] = lambda: next(server_message_iterator)
  File "/tudelft.net/staff-bulk/ewi/insy/DBL/swiergarst/envs/flower2en/lib/python3.9/site-packages/grpc/_channel.py", line 541, in __next__
    return self._next()
  File "/tudelft.net/staff-bulk/ewi/insy/DBL/swiergarst/envs/flower2en/lib/python3.9/site-packages/grpc/_channel.py", line 967, in _next
    raise self
grpc._channel._MultiThreadedRendezvous: <_MultiThreadedRendezvous of RPC that terminated with:
	status = StatusCode.UNAVAILABLE
	details = "Socket closed"
	debug_error_string = "UNKNOWN:Error received from peer ipv6:%5B::%5D:8080 {grpc_message:"Socket closed", grpc_status:14, created_time:"2024-01-18T11:26:42.530068338+01:00"}"
>
srun: error: influ4: tasks 6,9: Exited with exit code 1
srun: launch/slurm: _step_signal: Terminating StepId=9232958.1
slurmstepd: error: *** STEP 9232958.1 ON influ4 CANCELLED AT 2024-01-18T11:26:43 ***
slurmstepd: error: common_file_write_content: unable to open '/sys/fs/cgroup/freezer/slurm/uid_618619/job_9232958/step_1/freezer.state' for writing: Permission denied
srun: error: influ4: tasks 0-5,7-8: Terminated
srun: Force Terminated StepId=9232958.1
