INFO flwr 2024-01-17 15:23:05,208 | app.py:148 | Starting Flower server, config: ServerConfig(num_rounds=400, round_timeout=None)
INFO flwr 2024-01-17 15:23:05,264 | app.py:168 | Flower ECE: gRPC server running (400 rounds), SSL is disabled
INFO flwr 2024-01-17 15:23:05,264 | server.py:86 | Initializing global parameters
INFO flwr 2024-01-17 15:23:05,265 | server.py:273 | Requesting initial parameters from one random client
server booted up. starting clients...
INFO flwr 2024-01-17 15:23:46,776 | grpc.py:50 | Opened insecure gRPC connection (no certificates were passed)
INFO flwr 2024-01-17 15:23:46,787 | server.py:277 | Received initial parameters from one random client
INFO flwr 2024-01-17 15:23:46,788 | server.py:88 | Evaluating initial parameters
DEBUG flwr 2024-01-17 15:23:46,777 | connection.py:39 | ChannelConnectivity.IDLE
DEBUG flwr 2024-01-17 15:23:46,777 | connection.py:39 | ChannelConnectivity.CONNECTING
DEBUG flwr 2024-01-17 15:23:46,781 | connection.py:39 | ChannelConnectivity.READY
INFO flwr 2024-01-17 15:23:46,783 | grpc.py:50 | Opened insecure gRPC connection (no certificates were passed)
INFO flwr 2024-01-17 15:23:46,783 | grpc.py:50 | Opened insecure gRPC connection (no certificates were passed)
DEBUG flwr 2024-01-17 15:23:46,784 | connection.py:39 | ChannelConnectivity.IDLE
DEBUG flwr 2024-01-17 15:23:46,785 | connection.py:39 | ChannelConnectivity.CONNECTING
DEBUG flwr 2024-01-17 15:23:46,785 | connection.py:39 | ChannelConnectivity.IDLE
DEBUG flwr 2024-01-17 15:23:46,785 | connection.py:39 | ChannelConnectivity.CONNECTING
DEBUG flwr 2024-01-17 15:23:46,788 | connection.py:39 | ChannelConnectivity.READY
DEBUG flwr 2024-01-17 15:23:46,788 | connection.py:39 | ChannelConnectivity.READY
INFO flwr 2024-01-17 15:23:46,792 | grpc.py:50 | Opened insecure gRPC connection (no certificates were passed)
DEBUG flwr 2024-01-17 15:23:46,793 | connection.py:39 | ChannelConnectivity.IDLE
DEBUG flwr 2024-01-17 15:23:46,793 | connection.py:39 | ChannelConnectivity.CONNECTING
INFO flwr 2024-01-17 15:23:46,796 | grpc.py:50 | Opened insecure gRPC connection (no certificates were passed)
DEBUG flwr 2024-01-17 15:23:46,797 | connection.py:39 | ChannelConnectivity.READY
DEBUG flwr 2024-01-17 15:23:46,797 | connection.py:39 | ChannelConnectivity.IDLE
DEBUG flwr 2024-01-17 15:23:46,797 | connection.py:39 | ChannelConnectivity.CONNECTING
DEBUG flwr 2024-01-17 15:23:46,800 | connection.py:39 | ChannelConnectivity.READY
INFO flwr 2024-01-17 15:23:46,885 | grpc.py:50 | Opened insecure gRPC connection (no certificates were passed)
DEBUG flwr 2024-01-17 15:23:46,887 | connection.py:39 | ChannelConnectivity.IDLE
DEBUG flwr 2024-01-17 15:23:46,887 | connection.py:39 | ChannelConnectivity.CONNECTING
DEBUG flwr 2024-01-17 15:23:46,890 | connection.py:39 | ChannelConnectivity.READY
INFO flwr 2024-01-17 15:23:46,902 | grpc.py:50 | Opened insecure gRPC connection (no certificates were passed)
DEBUG flwr 2024-01-17 15:23:46,903 | connection.py:39 | ChannelConnectivity.IDLE
DEBUG flwr 2024-01-17 15:23:46,903 | connection.py:39 | ChannelConnectivity.CONNECTING
DEBUG flwr 2024-01-17 15:23:46,906 | connection.py:39 | ChannelConnectivity.READY
INFO flwr 2024-01-17 15:23:46,968 | grpc.py:50 | Opened insecure gRPC connection (no certificates were passed)
DEBUG flwr 2024-01-17 15:23:46,970 | connection.py:39 | ChannelConnectivity.IDLE
DEBUG flwr 2024-01-17 15:23:46,970 | connection.py:39 | ChannelConnectivity.CONNECTING
DEBUG flwr 2024-01-17 15:23:46,974 | connection.py:39 | ChannelConnectivity.READY
INFO flwr 2024-01-17 15:23:47,059 | grpc.py:50 | Opened insecure gRPC connection (no certificates were passed)
DEBUG flwr 2024-01-17 15:23:47,061 | connection.py:39 | ChannelConnectivity.IDLE
DEBUG flwr 2024-01-17 15:23:47,061 | connection.py:39 | ChannelConnectivity.CONNECTING
DEBUG flwr 2024-01-17 15:23:47,064 | connection.py:39 | ChannelConnectivity.READY
INFO flwr 2024-01-17 15:23:47,263 | grpc.py:50 | Opened insecure gRPC connection (no certificates were passed)
DEBUG flwr 2024-01-17 15:23:47,264 | connection.py:39 | ChannelConnectivity.IDLE
DEBUG flwr 2024-01-17 15:23:47,264 | connection.py:39 | ChannelConnectivity.CONNECTING
DEBUG flwr 2024-01-17 15:23:47,268 | connection.py:39 | ChannelConnectivity.READY
INFO flwr 2024-01-17 15:23:47,834 | server.py:91 | initial parameters (loss, other metrics): 2.308317865606674, {'accuracy': 0.1176}
INFO flwr 2024-01-17 15:23:47,834 | server.py:101 | FL starting
DEBUG flwr 2024-01-17 15:25:08,561 | server.py:218 | fit_round 1: strategy sampled 10 clients (out of 10)
DEBUG flwr 2024-01-17 15:25:13,665 | server.py:232 | fit_round 1 received 10 results and 0 failures
args.central: False
server strategy: ADMM
number of clients: 10
round:      0
Server-side evaluation loss 2.308317865606674 / accuracy 0.1176
Traceback (most recent call last):
  File "/tudelft.net/staff-bulk/ewi/insy/DBL/swiergarst/RP_FL/run_server.py", line 161, in <module>
    fl.server.start_server(config=fl.server.ServerConfig(num_rounds=NUM_ROUNDS), strategy=strat)
  File "/tudelft.net/staff-bulk/ewi/insy/DBL/swiergarst/envs/flower2en/lib/python3.9/site-packages/flwr/server/app.py", line 176, in start_server
    hist = _fl(
  File "/tudelft.net/staff-bulk/ewi/insy/DBL/swiergarst/envs/flower2en/lib/python3.9/site-packages/flwr/server/app.py", line 217, in _fl
    hist = server.fit(num_rounds=config.num_rounds, timeout=config.round_timeout)
  File "/tudelft.net/staff-bulk/ewi/insy/DBL/swiergarst/envs/flower2en/lib/python3.9/site-packages/flwr/server/server.py", line 106, in fit
    res_fit = self.fit_round(server_round=current_round, timeout=timeout)
  File "/tudelft.net/staff-bulk/ewi/insy/DBL/swiergarst/envs/flower2en/lib/python3.9/site-packages/flwr/server/server.py", line 244, in fit_round
    ] = self.strategy.aggregate_fit(server_round, results, failures)
  File "/tudelft.net/staff-bulk/ewi/insy/DBL/swiergarst/RP_FL/src/ADMM_strategy.py", line 28, in aggregate_fit
    y_local = json.loads(res.metrics["Y"].decode("utf-8"))
KeyError: 'Y'
Exception in thread Thread-1:
Traceback (most recent call last):
  File "/tudelft.net/staff-bulk/ewi/insy/DBL/swiergarst/envs/flower2en/lib/python3.9/threading.py", line 973, in _bootstrap_inner
    self.run()
  File "/tudelft.net/staff-bulk/ewi/insy/DBL/swiergarst/envs/flower2en/lib/python3.9/threading.py", line 910, in run
    self._target(*self._args, **self._kwargs)
  File "/tudelft.net/staff-bulk/ewi/insy/DBL/swiergarst/envs/flower2en/lib/python3.9/site-packages/grpc/_server.py", line 1212, in _serve
    if not _process_event_and_continue(state, event):
  File "/tudelft.net/staff-bulk/ewi/insy/DBL/swiergarst/envs/flower2en/lib/python3.9/site-packages/grpc/_server.py", line 1172, in _process_event_and_continue
    rpc_state, rpc_future = _handle_call(
  File "/tudelft.net/staff-bulk/ewi/insy/DBL/swiergarst/envs/flower2en/lib/python3.9/site-packages/grpc/_server.py", line 1049, in _handle_call
    return _handle_with_method_handler(
  File "/tudelft.net/staff-bulk/ewi/insy/DBL/swiergarst/envs/flower2en/lib/python3.9/site-packages/grpc/_server.py", line 987, in _handle_with_method_handler
    return state, _handle_stream_stream(
  File "/tudelft.net/staff-bulk/ewi/insy/DBL/swiergarst/envs/flower2en/lib/python3.9/site-packages/grpc/_server.py", line 914, in _handle_stream_stream
    return thread_pool.submit(
  File "/tudelft.net/staff-bulk/ewi/insy/DBL/swiergarst/envs/flower2en/lib/python3.9/concurrent/futures/thread.py", line 169, in submit
    raise RuntimeError('cannot schedule new futures after '
RuntimeError: cannot schedule new futures after interpreter shutdown
DEBUG flwr 2024-01-17 15:29:42,009 | connection.py:39 | ChannelConnectivity.IDLE
DEBUG flwr 2024-01-17 15:29:42,010 | connection.py:39 | ChannelConnectivity.IDLE
DEBUG flwr 2024-01-17 15:29:42,011 | connection.py:39 | ChannelConnectivity.IDLE
DEBUG flwr 2024-01-17 15:29:42,014 | connection.py:39 | ChannelConnectivity.IDLE
DEBUG flwr 2024-01-17 15:29:42,016 | connection.py:39 | ChannelConnectivity.IDLE
DEBUG flwr 2024-01-17 15:29:42,026 | connection.py:39 | ChannelConnectivity.IDLE
DEBUG flwr 2024-01-17 15:29:42,725 | connection.py:39 | ChannelConnectivity.IDLE
DEBUG flwr 2024-01-17 15:29:42,797 | connection.py:39 | ChannelConnectivity.IDLE
DEBUG flwr 2024-01-17 15:29:42,929 | connection.py:113 | gRPC channel closed
booting up client 0
Traceback (most recent call last):
  File "/tudelft.net/staff-bulk/ewi/insy/DBL/swiergarst/RP_FL/run_client.py", line 55, in <module>
    fl.client.start_numpy_client(server_address = "[::]:8080", client = client)
  File "/tudelft.net/staff-bulk/ewi/insy/DBL/swiergarst/envs/flower2en/lib/python3.9/site-packages/flwr/client/app.py", line 252, in start_numpy_client
    start_client(
  File "/tudelft.net/staff-bulk/ewi/insy/DBL/swiergarst/envs/flower2en/lib/python3.9/site-packages/flwr/client/app.py", line 174, in start_client
    server_message = receive()
  File "/tudelft.net/staff-bulk/ewi/insy/DBL/swiergarst/envs/flower2en/lib/python3.9/site-packages/flwr/client/grpc_client/connection.py", line 105, in <lambda>
    receive: Callable[[], ServerMessage] = lambda: next(server_message_iterator)
  File "/tudelft.net/staff-bulk/ewi/insy/DBL/swiergarst/envs/flower2en/lib/python3.9/site-packages/grpc/_channel.py", line 541, in __next__
    return self._next()
  File "/tudelft.net/staff-bulk/ewi/insy/DBL/swiergarst/envs/flower2en/lib/python3.9/site-packages/grpc/_channel.py", line 967, in _next
    raise self
grpc._channel._MultiThreadedRendezvous: <_MultiThreadedRendezvous of RPC that terminated with:
	status = StatusCode.UNAVAILABLE
	details = "ping timeout"
	debug_error_string = "UNKNOWN:Error received from peer ipv6:%5B::%5D:8080 {grpc_message:"ping timeout", grpc_status:14, created_time:"2024-01-17T15:29:42.724834057+01:00"}"
>
DEBUG flwr 2024-01-17 15:29:43,001 | connection.py:113 | gRPC channel closed
booting up client 0
Traceback (most recent call last):
  File "/tudelft.net/staff-bulk/ewi/insy/DBL/swiergarst/RP_FL/run_client.py", line 55, in <module>
    fl.client.start_numpy_client(server_address = "[::]:8080", client = client)
  File "/tudelft.net/staff-bulk/ewi/insy/DBL/swiergarst/envs/flower2en/lib/python3.9/site-packages/flwr/client/app.py", line 252, in start_numpy_client
    start_client(
  File "/tudelft.net/staff-bulk/ewi/insy/DBL/swiergarst/envs/flower2en/lib/python3.9/site-packages/flwr/client/app.py", line 174, in start_client
    server_message = receive()
  File "/tudelft.net/staff-bulk/ewi/insy/DBL/swiergarst/envs/flower2en/lib/python3.9/site-packages/flwr/client/grpc_client/connection.py", line 105, in <lambda>
    receive: Callable[[], ServerMessage] = lambda: next(server_message_iterator)
  File "/tudelft.net/staff-bulk/ewi/insy/DBL/swiergarst/envs/flower2en/lib/python3.9/site-packages/grpc/_channel.py", line 541, in __next__
    return self._next()
  File "/tudelft.net/staff-bulk/ewi/insy/DBL/swiergarst/envs/flower2en/lib/python3.9/site-packages/grpc/_channel.py", line 967, in _next
    raise self
grpc._channel._MultiThreadedRendezvous: <_MultiThreadedRendezvous of RPC that terminated with:
	status = StatusCode.UNAVAILABLE
	details = "ping timeout"
	debug_error_string = "UNKNOWN:Error received from peer ipv6:%5B::%5D:8080 {grpc_message:"ping timeout", grpc_status:14, created_time:"2024-01-17T15:29:42.796222783+01:00"}"
>
srun: error: gpu05: tasks 0,9: Exited with exit code 1
srun: launch/slurm: _step_signal: Terminating StepId=9231379.1
slurmstepd: error: *** STEP 9231379.1 ON gpu05 CANCELLED AT 2024-01-17T15:29:43 ***
slurmstepd: error: common_file_write_content: unable to open '/sys/fs/cgroup/freezer/slurm/uid_618619/job_9231379/step_1/freezer.state' for writing: Permission denied
srun: error: gpu05: tasks 1-8: Terminated
srun: Force Terminated StepId=9231379.1
